#VRML_SIM R2023b utf8

EXTERNPROTO "https://raw.githubusercontent.com/cyberbotics/webots/R2023b/projects/objects/backgrounds/protos/TexturedBackground.proto"
EXTERNPROTO "https://raw.githubusercontent.com/cyberbotics/webots/R2023b/projects/objects/backgrounds/protos/TexturedBackgroundLight.proto"
EXTERNPROTO "https://raw.githubusercontent.com/cyberbotics/webots/R2023b/projects/appearances/protos/CorrodedMetal.proto"

WorldInfo {
}
Viewpoint {
  orientation 0.06345894122332348 -0.0569482910179131 -0.9963582964621482 3.7532308126214016
  position 0.664436626170119 -0.3424962872567602 0.28932349392900353
}
TexturedBackground {
}
TexturedBackgroundLight {
}
Shape {
  appearance CorrodedMetal {
  }
  geometry Cylinder {
    height 0.019
    radius 0.77
  }
}
Robot {
  translation -0.008864663704457995 -0.012443828026216373 0.03904946374200927
  rotation -0.00016782855359855292 0.0005431117476638964 -0.99999983843159 2.5426333885650005
  children [
    InertialUnit {
      name "IMU"
    }
    HingeJoint {
      jointParameters HingeJointParameters {
        position 832.7074334433324
        anchor -0.05 0 0
      }
      device [
        PositionSensor {
          name "encoder_left"
        }
        RotationalMotor {
          name "motor_left"
        }
      ]
      endPoint Solid {
        translation -0.04999954940226955 8.648582461319654e-07 2.2652653653733794e-07
        rotation -0.7058685834394799 0.06556304520200684 -0.70530208422844 3.010551654668904
        children [
          DEF wheel_direita Shape {
            appearance PBRAppearance {
              baseColor 0.960784 0.47451 0
            }
            geometry Cylinder {
              height 0.01
              radius 0.03
            }
          }
        ]
        name "solid(1)"
        boundingObject USE wheel_direita
        physics DEF wheel_physics Physics {
        }
        linearVelocity -0.08808987116711471 0.1489241270942987 6.871061819339472e-05
        angularVelocity -5.460150114358971 -3.109898271106001 3.5527483713884105
      }
    }
    DEF Body Pose {
      children [
        Shape {
          appearance PBRAppearance {
            baseColor 0 0.5 1
          }
          geometry Cylinder {
            height 0.05
            radius 0.05
          }
        }
      ]
    }
    HingeJoint {
      jointParameters HingeJointParameters {
        position -634.1232680378627
        anchor 0.05 0 0
      }
      device [
        PositionSensor {
          name "encoder_right"
        }
        RotationalMotor {
          name "motor_direita"
        }
      ]
      endPoint Solid {
        translation 0.050000449468013734 -4.814778583867558e-07 -3.7868396440969335e-07
        rotation 0.23073916861172802 0.9453060297385566 0.2305557334101576 1.6262113550164095
        children [
          DEF wheel Shape {
            appearance PBRAppearance {
              baseColor 0.960784 0.47451 0
            }
            geometry Cylinder {
              height 0.01
              radius 0.03
            }
          }
        ]
        boundingObject USE wheel
        physics DEF wheel_physics Physics {
        }
        linearVelocity 0.0877040141694137 -0.14886607261706847 -3.300956533809818e-05
        angularVelocity 5.458643067452169 3.1067600678963485 3.55234353894887
      }
    }
  ]
  name "MX0"
  boundingObject USE Body
  physics Physics {
  }
  controller "MXO_main"
  linearVelocity -0.0001936158726298522 2.838685763800146e-05 1.3518737777936664e-05
  angularVelocity -0.0006834794746975281 -0.0017129798923631893 3.3836075843848206
}
Solid {
  children [
    DEF arena Shape {
      geometry Cylinder {
        height 0.019
        radius 0.77
      }
    }
  ]
  boundingObject USE arena
}
